Workbook

Sheet Pivot table 2
A3: Age | B3: Average of charges
A4: 18 | B4: 22539.556
A5: 19 | B5: 26436.838
A6: 20 | B6: 23933.689
A7: 21 | B7: 16919.117
A8: 22 | B8: 30026.682
A9: 23 | B9: 26061.338
A10: 24 | B10: 25858.909
A11: 25 | B11: 24760.697
A12: 26 | B12: 17566.633
A13: 27 | B13: 24531.522
A14: 28 | B14: 24778.54
A15: 29 | B15: 23141.134
... A51: 65 | B51: 29330.98
A52: #N/A | B52: #N/A
A53: Grand Total | B53: #N/A

Sheet Pivot table 1
B2: Cancer history
B3: No | C3: Yes | D3: #N/A | E3: Grand Total
A4: Count of smoker | B4: 1944 | C4: 391 | D4: 1 | E4: 2336
A6: Any Transplants | B6: Average of HBA1C | C6: Count of NumberOfMajorSurgeries
A7: No | B7: 6.6704427 | C7: 2191
A8: yes | B8: 5.1876389 | C8: 144
A9: #N/A | B9: #N/A | C9: 1
A10: Grand Total | B10: #N/A | C10: #N/A
A12: Weight status | B12: Diabetes status | C12: Count of charges
A13: obesity | C13: 1221
A14: normal weight | C14: 431
A15: over weight | C15: 507
A16: under weight | C16: 176
A17: #N/A | B17: #N/A | C17: 1
A18: #N/A Total | C18: 1
A19: Grand Total | C19: 2336
A35: Hospital tier | B35: State ID | C35: Sum of charges
A36: tier - 1 | C36: 9020911.9
A37: tier - 2 | C37: 11331149
A38: tier - 3 | C38: 5349293.6
A39: #N/A | B39: #N/A | C39: #N/A
A40: #N/A Total | C40: #N/A
A41: Grand Total | C41: #N/A
A43: Age | B43: (All)
A45: Count of Weight | B45: Weight status
A46: Diabetes status | B46: obesity | C46: normal weight | D46: over weight | E46: under weight | F46: #N/A | G46: Grand Total
A47: diabetes | B47: 423 | C47: 137 | D47: 159 | E47: 65 | G47: 784
A48: normal | B48: 561 | C48: 212 | D48: 240 | E48: 82 | G48: 1095
A49: prediabetes | B49: 237 | C49: 82 | D49: 108 | E49: 29 | G49: 456
A50: #N/A | F50: 1 | G50: 1
A51: Grand Total | B51: 1221 | C51: 431 | D51: 507 | E51: 176 | F51: 1 | G51: 2336

Sheet Dashboard 
C1: HEALTH CARE SENTTING DATA DASHBOARD
A4: Any Transplants | B4: Average of HBA1C | C4: Count of NumberOfMajorSurgeries | H4: Age | I4: (All)
A5: No | B5: 6.6704427 | C5: 2191
A6: yes | B6: 5.1876389 | C6: 144 | H6: Count of Weight | I6: Weight status
A7: Grand Total | B7: 6.5789979 | C7: 2335 | H7: Diabetes status | I7: obesity | J7: normal weight | K7: over weight | L7: under weight | M7: Grand Total
H8: diabetes | I8: 423 | J8: 137 | K8: 159 | L8: 65 | M8: 784
H9: normal | I9: 561 | J9: 212 | K9: 240 | L9: 82 | M9: 1095
H10: prediabetes | I10: 237 | J10: 82 | K10: 108 | L10: 29 | M10: 456
A11: Weight status | B11: Diabetes status | C11: Count of charges | H11: Grand Total | I11: 1221 | J11: 431 | K11: 507 | L11: 176 | M11: 2335
A12: obesity | C12: 1221
A13: normal weight | C13: 431
A14: over weight | C14: 507
A15: under weight | C15: 176
A16: Grand Total | C16: 2335
A18: Hospital tier | B18: State ID | C18: Sum of charges
A19: tier - 1 | C19: 9020911.9
A20: tier - 2 | C20: 11331149
A21: tier - 3 | C21: 5349293.6
A22: Grand Total | C22: 25701355

Sheet Customer Names
A1: Column1 | B1: Column2 | C1: Column3 | D1: Column32 | E1: Column33 | F1: Column4 | G1: Column5 | H1: Column6 | I1: Column7 | J1: Column8 | K1: Column9 | L1: Column10 | M1: Column11
A2: Customer ID | B2: name | C2: Title | D2: =Table5[[#This Row],[Column5]]&" "&Table5[[#This Row],[Column7]]&" "
A3: Id1 | B3: Hawks | C3: =B3&" "&F3 -> Hawks | D3: =Table5[[#This Row],[Column5]]&" "&Table5[[#This Row],[Column7]]&" " -> Ms. Kelly | G3: Ms. | I3: Kelly
A4: Id2 | B4: Lehner | C4: =B4&" "&F4 -> Lehner | D4: =Table5[[#This Row],[Column5]]&" "&Table5[[#This Row],[Column7]]&" " -> Mr. Matthew | E4: D | G4: Mr. | I4: Matthew | J4: D
A5: Id3 | B5: Lu | C5: =B5&" "&F5 -> Lu | D5: =Table5[[#This Row],[Column5]]&" "&Table5[[#This Row],[Column7]]&" " -> Mr. Phil | G5: Mr. | I5: Phil
A6: Id4 | B6: Osborne | C6: =B6&" "&F6 -> Osborne | D6: =Table5[[#This Row],[Column5]]&" "&Table5[[#This Row],[Column7]]&" " -> Ms. Kelsey | G6: Ms. | I6: Kelsey
A7: Id5 | B7: Kadala | C7: =B7&" "&F7 -> Kadala | D7: =Table5[[#This Row],[Column5]]&" "&Table5[[#This Row],[Column7]]&" " -> Ms. Kristyn | G7: Ms. | I7: Kristyn
A8: Id6 | B8: Baker | C8: =B8&" "&F8 -> Baker | D8: =Table5[[#This Row],[Column5]]&" "&Table5[[#This Row],[Column7]]&" " -> Mr. Russell | E8: B. | G8: Mr. | I8: Russell | J8: B.
A9: Id7 | B9: Macpherson | C9: =B9&" "&F9 -> Macpherson | D9: =Table5[[#This Row],[Column5]]&" "&Table5[[#This Row],[Column7]]&" " -> Mr. Scott | G9: Mr. | I9: Scott
A10: Id8 | B10: Hallman | C10: =B10&" "&F10 -> Hallman | D10: =Table5[[#This Row],[Column5]]&" "&Table5[[#This Row],[Column7]]&" " -> Mr. Stephen | G10: Mr. | I10: Stephen
A11: Id9 | B11: Moran | C11: =B11&" "&F11 -> Moran | D11: =Table5[[#This Row],[Column5]]&" "&Table5[[#This Row],[Column7]]&" " -> Mr. Patrick | E11: R. | G11: Mr. | I11: Patrick | J11: R.
A12: Id10 | B12: Benner | C12: =B12&" "&F12 -> Benner | D12: =Table5[[#This Row],[Column5]]&" "&Table5[[#This Row],[Column7]]&" " -> Ms. Brooke | E12: N. | G12: Ms. | I12: Brooke | J12: N.
A13: Id11 | B13: Fierro | C13: =B13&" "&F13 -> Fierro Vargas | D13: =Table5[[#This Row],[Column6]]&" "&Table5[[#This Row],[Column8]]&" " -> Ms. Paola | E13: Andrea | F13: Vargas | H13: Ms. | J13: Paola
A14: Id12 | B14: Franz | C14: =B14&" "&F14 -> Franz | D14: =Table5[[#This Row],[Column5]]&" "&Table5[[#This Row],[Column7]]&" " -> Mr. David | G14: Mr. | I14: David
A15: Id13 | B15: Foster | C15: =B15&" "&F15 -> Foster | D15: =Table5[[#This Row],[Column5]]&" "&Table5[[#This Row],[Column7]]&" " -> Mr. Wade | G15: Mr. | I15: Wade
A16: Id14 | B16: Tenorio | C16: =B16&" "&F16 -> Tenorio | D16: =Table5[[#This Row],[Column5]]&" "&Table5[[#This Row],[Column7]]&" " -> Mr. Franklin | G16: Mr. | I16: Franklin
A17: Id15 | B17: Rios | C17: =B17&" "&F17 -> Rios | D17: =Table5[[#This Row],[Column5]]&" "&Table5[[#This Row],[Column7]]&" " -> Ms. Leilani | E17: M. | G17: Ms. | I17: Leilani | J17: M.
A18: Id16 | B18: Viau-Dupuis | C18: =B18&" "&F18 -> Viau-Dupuis | D18: =Table5[[#This Row],[Column5]]&" "&Table5[[#This Row],[Column7]]&" " -> Mr. Philippe | G18: Mr. | I18: Philippe
A19: Id17 | B19: Cronin | C19: =B19&" "&F19 -> Cronin | D19: =Table5[[#This Row],[Column5]]&" "&Table5[[#This Row],[Column7]]&" " -> Ms. Jennifer | E19: A. | G19: Ms. | I19: Jennifer | J19: A.
A20: Id18 | B20: Noordstar | C20: =B20&" "&F20 -> Noordstar | D20: =Table5[[#This Row],[Column5]]&" "&Table5[[#This Row],[Column7]]&" " -> Ms. Christina | E20: M. | G20: Ms. | I20: Christina | J20: M.
A21: Id19 | B21: Boudalia | C21: =B21&" "&F21 -> Boudalia | D21: =Table5[[#This Row],[Column5]]&" "&Table5[[#This Row],[Column7]]&" " -> Mr. Said | E21: Sr. | G21: Mr. | I21: Said | J21: Sr.
A22: Id20 | B22: Flor | C22: =B22&" "&F22 -> Flor | D22: =Table5[[#This Row],[Column5]]&" "&Table5[[#This Row],[Column7]]&" " -> Mr. John | G22: Mr. | I22: John
A23: Id21 | B23: Fennon | C23: =B23&" "&F23 -> Fennon | D23: =Table5[[#This Row],[Column5]]&" "&Table5[[#This Row],[Column7]]&" " -> Mr. Myles | G23: Mr. | I23: Myles
A24: Id22 | B24: Hribar | C24: =B24&" "&F24 -> Hribar | D24: =Table5[[#This Row],[Column5]]&" "&Table5[[#This Row],[Column7]]&" " -> Ms. Madelyn | E24: C | G24: Ms. | I24: Madelyn | J24: C
A25: Id23 | B25: Tassello | C25: =B25&" "&F25 -> Tassello | D25: =Table5[[#This Row],[Column5]]&" "&Table5[[#This Row],[Column7]]&" " -> Ms. Nicole | G25: Ms. | I25: Nicole
A26: Id24 | B26: Mauricette | C26: =B26&" "&F26 -> Mauricette | D26: =Table5[[#This Row],[Column5]]&" "&Table5[[#This Row],[Column7]]&" " -> Mr. Eric | E26: A. | G26: Mr. | I26: Eric | J26: A.
A27: Id25 | B27: Garcia | C27: =B27&" "&F27 -> Garcia | D27: =Table5[[#This Row],[Column5]]&" "&Table5[[#This Row],[Column7]]&" " -> Mr. Emiliano | E27: I. | G27: Mr. | I27: Emiliano | J27: I.
A28: Id26 | B28: Airoldi | C28: =B28&" "&F28 -> Airoldi | D28: =Table5[[#This Row],[Column5]]&" "&Table5[[#This Row],[Column7]]&" " -> Mr. Adam | G28: Mr. | I28: Adam
A29: Id27 | B29: Cater-Cyker | C29: =B29&" "&F29 -> Cater-Cyker | D29: =Table5[[#This Row],[Column5]]&" "&Table5[[#This Row],[Column7]]&" " -> Mr. Zach | G29: Mr. | I29: Zach
A30: Id28 | B30: Hamm | C30: =B30&" "&F30 -> Hamm | D30: =Table5[[#This Row],[Column5]]&" "&Table5[[#This Row],[Column7]]&" " -> Ms. Stephanie | E30: W. | G30: Ms. | I30: Stephanie | J30: W.
A31: Id29 | B31: Cox | C31: =B31&" "&F31 -> Cox | D31: =Table5[[#This Row],[Column5]]&" "&Table5[[#This Row],[Column7]]&" " -> Mr. Stephen | G31: Mr. | I31: Stephen
A32: Id30 | B32: Sachrajda | C32: =B32&" "&F32 -> Sachrajda | D32: =Table5[[#This Row],[Column5]]&" "&Table5[[#This Row],[Column7]]&" " -> Ms. Natalie | G32: Ms. | I32: Natalie
A33: Id31 | B33: Gareri | C33: =B33&" "&F33 -> Gareri | D33: =Table5[[#This Row],[Column5]]&" "&Table5[[#This Row],[Column7]]&" " -> Ms. Nicole | E33: J. | G33: Ms. | I33: Nicole | J33: J.
A34: Id32 | B34: Welch | C34: =B34&" "&F34 -> Welch | D34: =Table5[[#This Row],[Column5]]&" "&Table5[[#This Row],[Column7]]&" " -> Mr. Jefferson | E34: D | G34: Mr. | I34: Jefferson | J34: D
A35: Id33 | B35: Prindiville | C35: =B35&" "&F35 -> Prindiville | D35: =Table5[[#This Row],[Column5]]&" "&Table5[[#This Row],[Column7]]&" " -> Mr. Brendan | E35: D. | G35: Mr. | I35: Brendan | J35: D.
A36: Id34 | B36: Kincaid | C36: =B36&" "&F36 -> Kincaid | D36: =Table5[[#This Row],[Column5]]&" "&Table5[[#This Row],[Column7]]&" " -> Ms. Courtney | G36: Ms. | I36: Courtney
A37: Id35 | B37: Bruestle | C37: =B37&" "&F37 -> Bruestle | D37: =Table5[[#This Row],[Column5]]&" "&Table5[[#This Row],[Column7]]&" " -> Ms. Sydney | E37: L. | G37: Ms. | I37: Sydney | J37: L.
A38: Id36 | B38: Lachance | C38: =B38&" "&F38 -> Lachance | D38: =Table5[[#This Row],[Column5]]&" "&Table5[[#This Row],[Column7]]&" " -> Mr. Julien | G38: Mr. | I38: Julien
A39: Id37 | B39: Eason | C39: =B39&" "&F39 -> Eason | D39: =Table5[[#This Row],[Column5]]&" "&Table5[[#This Row],[Column7]]&" " -> Mr. Ryan | E39: M | G39: Mr. | I39: Ryan | J39: M
A40: Id38 | B40: Grummon | C40: =B40&" "&F40 -> Grummon | D40: =Table5[[#This Row],[Column5]]&" "&Table5[[#This Row],[Column7]]&" " -> Ms. Anna | E40: H. | G40: Ms. | I40: Anna | J40: H.
...

Sheet Customer name 1
A1: Column1 | B1: Column2 | C1: Column3 | D1: First name | E1: Last name
A2: Customer ID | B2: name | C2: Title | D2: =Table5[[#This Row],[Column5]]&" "&Table5[[#This Row],[Column7]]&" "
A3: Id1 | B3: Hawks | C3: =B3&" "&F3 -> Hawks | D3: =Table5[[#This Row],[Column5]]&" "&Table5[[#This Row],[Column7]]&" " -> Ms. Kelly
A4: Id2 | B4: Lehner | C4: =B4&" "&F4 -> Lehner | D4: =Table5[[#This Row],[Column5]]&" "&Table5[[#This Row],[Column7]]&" " -> Mr. Matthew | E4: D
A5: Id3 | B5: Lu | C5: =B5&" "&F5 -> Lu | D5: =Table5[[#This Row],[Column5]]&" "&Table5[[#This Row],[Column7]]&" " -> Mr. Phil
A6: Id4 | B6: Osborne | C6: =B6&" "&F6 -> Osborne | D6: =Table5[[#This Row],[Column5]]&" "&Table5[[#This Row],[Column7]]&" " -> Ms. Kelsey
A7: Id5 | B7: Kadala | C7: =B7&" "&F7 -> Kadala | D7: =Table5[[#This Row],[Column5]]&" "&Table5[[#This Row],[Column7]]&" " -> Ms. Kristyn
A8: Id6 | B8: Baker | C8: =B8&" "&F8 -> Baker | D8: =Table5[[#This Row],[Column5]]&" "&Table5[[#This Row],[Column7]]&" " -> Mr. Russell | E8: B.
A9: Id7 | B9: Macpherson | C9: =B9&" "&F9 -> Macpherson | D9: =Table5[[#This Row],[Column5]]&" "&Table5[[#This Row],[Column7]]&" " -> Mr. Scott
A10: Id8 | B10: Hallman | C10: =B10&" "&F10 -> Hallman | D10: =Table5[[#This Row],[Column5]]&" "&Table5[[#This Row],[Column7]]&" " -> Mr. Stephen
A11: Id9 | B11: Moran | C11: =B11&" "&F11 -> Moran | D11: =Table5[[#This Row],[Column5]]&" "&Table5[[#This Row],[Column7]]&" " -> Mr. Patrick | E11: R.
A12: Id10 | B12: Benner | C12: =B12&" "&F12 -> Benner | D12: =Table5[[#This Row],[Column5]]&" "&Table5[[#This Row],[Column7]]&" " -> Ms. Brooke | E12: N.
A13: Id11 | B13: Fierro | C13: =B13&" "&F13 -> Fierro | D13: =Table5[[#This Row],[Column6]]&" "&Table5[[#This Row],[Column8]]&" " -> Ms. Paola | E13: Andrea
A14: Id12 | B14: Franz | C14: =B14&" "&F14 -> Franz | D14: =Table5[[#This Row],[Column5]]&" "&Table5[[#This Row],[Column7]]&" " -> Mr. David
A15: Id13 | B15: Foster | C15: =B15&" "&F15 -> Foster | D15: =Table5[[#This Row],[Column5]]&" "&Table5[[#This Row],[Column7]]&" " -> Mr. Wade
A16: Id14 | B16: Tenorio | C16: =B16&" "&F16 -> Tenorio | D16: =Table5[[#This Row],[Column5]]&" "&Table5[[#This Row],[Column7]]&" " -> Mr. Franklin
A17: Id15 | B17: Rios | C17: =B17&" "&F17 -> Rios | D17: =Table5[[#This Row],[Column5]]&" "&Table5[[#This Row],[Column7]]&" " -> Ms. Leilani | E17: M.
A18: Id16 | B18: Viau-Dupuis | C18: =B18&" "&F18 -> Viau-Dupuis | D18: =Table5[[#This Row],[Column5]]&" "&Table5[[#This Row],[Column7]]&" " -> Mr. Philippe
A19: Id17 | B19: Cronin | C19: =B19&" "&F19 -> Cronin | D19: =Table5[[#This Row],[Column5]]&" "&Table5[[#This Row],[Column7]]&" " -> Ms. Jennifer | E19: A.
A20: Id18 | B20: Noordstar | C20: =B20&" "&F20 -> Noordstar | D20: =Table5[[#This Row],[Column5]]&" "&Table5[[#This Row],[Column7]]&" " -> Ms. Christina | E20: M.
A21: Id19 | B21: Boudalia | C21: =B21&" "&F21 -> Boudalia | D21: =Table5[[#This Row],[Column5]]&" "&Table5[[#This Row],[Column7]]&" " -> Mr. Said | E21: Sr.
A22: Id20 | B22: Flor | C22: =B22&" "&F22 -> Flor | D22: =Table5[[#This Row],[Column5]]&" "&Table5[[#This Row],[Column7]]&" " -> Mr. John
A23: Id21 | B23: Fennon | C23: =B23&" "&F23 -> Fennon | D23: =Table5[[#This Row],[Column5]]&" "&Table5[[#This Row],[Column7]]&" " -> Mr. Myles
A24: Id22 | B24: Hribar | C24: =B24&" "&F24 -> Hribar | D24: =Table5[[#This Row],[Column5]]&" "&Table5[[#This Row],[Column7]]&" " -> Ms. Madelyn | E24: C
A25: Id23 | B25: Tassello | C25: =B25&" "&F25 -> Tassello | D25: =Table5[[#This Row],[Column5]]&" "&Table5[[#This Row],[Column7]]&" " -> Ms. Nicole
A26: Id24 | B26: Mauricette | C26: =B26&" "&F26 -> Mauricette | D26: =Table5[[#This Row],[Column5]]&" "&Table5[[#This Row],[Column7]]&" " -> Mr. Eric | E26: A.
A27: Id25 | B27: Garcia | C27: =B27&" "&F27 -> Garcia | D27: =Table5[[#This Row],[Column5]]&" "&Table5[[#This Row],[Column7]]&" " -> Mr. Emiliano | E27: I.
A28: Id26 | B28: Airoldi | C28: =B28&" "&F28 -> Airoldi | D28: =Table5[[#This Row],[Column5]]&" "&Table5[[#This Row],[Column7]]&" " -> Mr. Adam
A29: Id27 | B29: Cater-Cyker | C29: =B29&" "&F29 -> Cater-Cyker | D29: =Table5[[#This Row],[Column5]]&" "&Table5[[#This Row],[Column7]]&" " -> Mr. Zach
A30: Id28 | B30: Hamm | C30: =B30&" "&F30 -> Hamm | D30: =Table5[[#This Row],[Column5]]&" "&Table5[[#This Row],[Column7]]&" " -> Ms. Stephanie | E30: W.
A31: Id29 | B31: Cox | C31: =B31&" "&F31 -> Cox | D31: =Table5[[#This Row],[Column5]]&" "&Table5[[#This Row],[Column7]]&" " -> Mr. Stephen
A32: Id30 | B32: Sachrajda | C32: =B32&" "&F32 -> Sachrajda | D32: =Table5[[#This Row],[Column5]]&" "&Table5[[#This Row],[Column7]]&" " -> Ms. Natalie
A33: Id31 | B33: Gareri | C33: =B33&" "&F33 -> Gareri | D33: =Table5[[#This Row],[Column5]]&" "&Table5[[#This Row],[Column7]]&" " -> Ms. Nicole | E33: J.
A34: Id32 | B34: Welch | C34: =B34&" "&F34 -> Welch | D34: =Table5[[#This Row],[Column5]]&" "&Table5[[#This Row],[Column7]]&" " -> Mr. Jefferson | E34: D
A35: Id33 | B35: Prindiville | C35: =B35&" "&F35 -> Prindiville | D35: =Table5[[#This Row],[Column5]]&" "&Table5[[#This Row],[Column7]]&" " -> Mr. Brendan | E35: D.
A36: Id34 | B36: Kincaid | C36: =B36&" "&F36 -> Kincaid | D36: =Table5[[#This Row],[Column5]]&" "&Table5[[#This Row],[Column7]]&" " -> Ms. Courtney
A37: Id35 | B37: Bruestle | C37: =B37&" "&F37 -> Bruestle | D37: =Table5[[#This Row],[Column5]]&" "&Table5[[#This Row],[Column7]]&" " -> Ms. Sydney | E37: L.
A38: Id36 | B38: Lachance | C38: =B38&" "&F38 -> Lachance | D38: =Table5[[#This Row],[Column5]]&" "&Table5[[#This Row],[Column7]]&" " -> Mr. Julien
A39: Id37 | B39: Eason | C39: =B39&" "&F39 -> Eason | D39: =Table5[[#This Row],[Column5]]&" "&Table5[[#This Row],[Column7]]&" " -> Mr. Ryan | E39: M
A40: Id38 | B40: Grummon | C40: =B40&" "&F40 -> Grummon | D40: =Table5[[#This Row],[Column5]]&" "&Table5[[#This Row],[Column7]]&" " -> Ms. Anna | E40: H.
...

Sheet Medical Examinations
A1: Customer ID | B1: BMI | C1: Weight status | D1: HBA1C | E1: Column1 | F1: Heart Issues | G1: Any Transplants | H1: Cancer history | I1: NumberOfMajorSurgeries | J1: smoker
A2: Id1 | B2: 47.41 | C2: =IF(Table2[[#This Row],[BMI]]<18.5,"under weight ",IF(Table2[[#This Row],[BMI]]<24.9,"normal weight",IF(Table2[[#This Row],[BMI]]<30,"over weight",IF(Table2[[#This Row],[BMI]]>29.9," obesity ")))) -> obesity | D2: 7.47 | E2: =IF(Table2[[#This Row],[HBA1C]]<5.7,"normal ",IF(Table2[[#This Row],[HBA1C]]<6.5,"prediabetes",IF(Table2[[#This Row],[HBA1C]]=6.5>6.5,"diabetes "))) -> diabetes | F2: No | G2: No | H2: No | I2: 0 | J2: yes
A3: Id2 | B3: 30.36 | C3: =IF(Table2[[#This Row],[BMI]]<18.5,"under weight ",IF(Table2[[#This Row],[BMI]]<24.9,"normal weight",IF(Table2[[#This Row],[BMI]]<30,"over weight",IF(Table2[[#This Row],[BMI]]>29.9," obesity ")))) -> obesity | D3: 5.77 | E3: =IF(Table2[[#This Row],[HBA1C]]<5.7,"normal ",IF(Table2[[#This Row],[HBA1C]]<6.5,"prediabetes",IF(Table2[[#This Row],[HBA1C]]=6.5>6.5,"diabetes "))) -> prediabetes | F3: No | G3: No | H3: No | I3: 0 | J3: yes
A4: Id3 | B4: 34.485 | C4: =IF(Table2[[#This Row],[BMI]]<18.5,"under weight ",IF(Table2[[#This Row],[BMI]]<24.9,"normal weight",IF(Table2[[#This Row],[BMI]]<30,"over weight",IF(Table2[[#This Row],[BMI]]>29.9," obesity ")))) -> obesity | D4: 11.87 | E4: =IF(Table2[[#This Row],[HBA1C]]<5.7,"normal ",IF(Table2[[#This Row],[HBA1C]]<6.5,"prediabetes",IF(Table2[[#This Row],[HBA1C]]=6.5>6.5,"diabetes "))) -> diabetes | F4: yes | G4: No | H4: No | I4: 2 | J4: yes | M4: =COUNTIF(Table2[Customer ID],"?") -> 0
A5: Id4 | B5: 38.095 | C5: =IF(Table2[[#This Row],[BMI]]<18.5,"under weight ",IF(Table2[[#This Row],[BMI]]<24.9,"normal weight",IF(Table2[[#This Row],[BMI]]<30,"over weight",IF(Table2[[#This Row],[BMI]]>29.9," obesity ")))) -> obesity | D5: 6.05 | E5: =IF(Table2[[#This Row],[HBA1C]]<5.7,"normal ",IF(Table2[[#This Row],[HBA1C]]<6.5,"prediabetes",IF(Table2[[#This Row],[HBA1C]]=6.5>6.5,"diabetes "))) -> prediabetes | F5: No | G5: No | H5: No | I5: 0 | J5: yes | M5: =COUNTIF(Table2[BMI],"?") -> 0
A6: Id5 | B6: 35.53 | C6: =IF(Table2[[#This Row],[BMI]]<18.5,"under weight ",IF(Table2[[#This Row],[BMI]]<24.9,"normal weight",IF(Table2[[#This Row],[BMI]]<30,"over weight",IF(Table2[[#This Row],[BMI]]>29.9," obesity ")))) -> obesity | D6: 5.45 | E6: =IF(Table2[[#This Row],[HBA1C]]<5.7,"normal ",IF(Table2[[#This Row],[HBA1C]]<6.5,"prediabetes",IF(Table2[[#This Row],[HBA1C]]=6.5>6.5,"diabetes "))) -> normal | F6: No | G6: No | H6: No | I6: 0 | J6: yes | M6: =COUNTIF(Table2[HBA1C],"?") -> 0
A7: Id6 | B7: 32.8 | C7: =IF(Table2[[#This Row],[BMI]]<18.5,"under weight ",IF(Table2[[#This Row],[BMI]]<24.9,"normal weight",IF(Table2[[#This Row],[BMI]]<30,"over weight",IF(Table2[[#This Row],[BMI]]>29.9," obesity ")))) -> obesity | D7: 6.59 | E7: =IF(Table2[[#This Row],[HBA1C]]<5.7,"normal ",IF(Table2[[#This Row],[HBA1C]]<6.5,"prediabetes",IF(Table2[[#This Row],[HBA1C]]=6.5>6.5,"diabetes "))) -> diabetes | F7: No | G7: No | H7: No | I7: 0 | J7: yes | M7: =COUNTIF(Table2[Heart Issues],"?") -> 0
A8: Id7 | B8: 36.4 | C8: =IF(Table2[[#This Row],[BMI]]<18.5,"under weight ",IF(Table2[[#This Row],[BMI]]<24.9,"normal weight",IF(Table2[[#This Row],[BMI]]<30,"over weight",IF(Table2[[#This Row],[BMI]]>29.9," obesity ")))) -> obesity | D8: 6.07 | E8: =IF(Table2[[#This Row],[HBA1C]]<5.7,"normal ",IF(Table2[[#This Row],[HBA1C]]<6.5,"prediabetes",IF(Table2[[#This Row],[HBA1C]]=6.5>6.5,"diabetes "))) -> prediabetes | F8: No | G8: No | H8: No | I8: 0 | J8: yes | M8: =COUNTIF(Table2[Any Transplants],"?") -> 0
A9: Id8 | B9: 36.96 | C9: =IF(Table2[[#This Row],[BMI]]<18.5,"under weight ",IF(Table2[[#This Row],[BMI]]<24.9,"normal weight",IF(Table2[[#This Row],[BMI]]<30,"over weight",IF(Table2[[#This Row],[BMI]]>29.9," obesity ")))) -> obesity | D9: 7.93 | E9: =IF(Table2[[#This Row],[HBA1C]]<5.7,"normal ",IF(Table2[[#This Row],[HBA1C]]<6.5,"prediabetes",IF(Table2[[#This Row],[HBA1C]]=6.5>6.5,"diabetes "))) -> diabetes | F9: No | G9: No | H9: No | I9: 3 | J9: yes | M9: =COUNTIF(Table2[Cancer history],"?") -> 0
A10: Id9 | B10: 41.14 | C10: =IF(Table2[[#This Row],[BMI]]<18.5,"under weight ",IF(Table2[[#This Row],[BMI]]<24.9,"normal weight",IF(Table2[[#This Row],[BMI]]<30,"over weight",IF(Table2[[#This Row],[BMI]]>29.9," obesity ")))) -> obesity | D10: 9.58 | E10: =IF(Table2[[#This Row],[HBA1C]]<5.7,"normal ",IF(Table2[[#This Row],[HBA1C]]<6.5,"prediabetes",IF(Table2[[#This Row],[HBA1C]]=6.5>6.5,"diabetes "))) -> diabetes | F10: yes | G10: No | H10: Yes | I10: 1 | J10: yes | M10: =COUNTIF(Table2[NumberOfMajorSurgeries],"?") -> 0
A11: Id10 | B11: 38.06 | C11: =IF(Table2[[#This Row],[BMI]]<18.5,"under weight ",IF(Table2[[#This Row],[BMI]]<24.9,"normal weight",IF(Table2[[#This Row],[BMI]]<30,"over weight",IF(Table2[[#This Row],[BMI]]>29.9," obesity ")))) -> obesity | D11: 10.79 | E11: =IF(Table2[[#This Row],[HBA1C]]<5.7,"normal ",IF(Table2[[#This Row],[HBA1C]]<6.5,"prediabetes",IF(Table2[[#This Row],[HBA1C]]=6.5>6.5,"diabetes "))) -> diabetes | F11: No | G11: No | H11: No | I11: 0 | J11: yes | M11: =COUNTIF(Table2[smoker],"?") -> 0
A12: Id11 | B12: 37.7 | C12: =IF(Table2[[#This Row],[BMI]]<18.5,"under weight ",IF(Table2[[#This Row],[BMI]]<24.9,"normal weight",IF(Table2[[#This Row],[BMI]]<30,"over weight",IF(Table2[[#This Row],[BMI]]>29.9," obesity ")))) -> obesity | D12: 5.96 | E12: =IF(Table2[[#This Row],[HBA1C]]<5.7,"normal ",IF(Table2[[#This Row],[HBA1C]]<6.5,"prediabetes",IF(Table2[[#This Row],[HBA1C]]=6.5>6.5,"diabetes "))) -> prediabetes | F12: yes | G12: No | H12: No | I12: 2 | J12: yes | L12: Total count of "?" | M12: =SUM(M4:M11) -> 0
A13: Id12 | B13: 42.13 | C13: =IF(Table2[[#This Row],[BMI]]<18.5,"under weight ",IF(Table2[[#This Row],[BMI]]<24.9,"normal weight",IF(Table2[[#This Row],[BMI]]<30,"over weight",IF(Table2[[#This Row],[BMI]]>29.9," obesity ")))) -> obesity | D13: 11.9 | E13: =IF(Table2[[#This Row],[HBA1C]]<5.7,"normal ",IF(Table2[[#This Row],[HBA1C]]<6.5,"prediabetes",IF(Table2[[#This Row],[HBA1C]]=6.5>6.5,"diabetes "))) -> diabetes | F13: No | G13: No | H13: No | I13: 0 | J13: yes | K13: Smoker | L13: Yes | M13: =COUNTIF(Table2[smoker],"yes") -> 490
A14: Id13 | B14: 40.92 | C14: =IF(Table2[[#This Row],[BMI]]<18.5,"under weight ",IF(Table2[[#This Row],[BMI]]<24.9,"normal weight",IF(Table2[[#This Row],[BMI]]<30,"over weight",IF(Table2[[#This Row],[BMI]]>29.9," obesity ")))) -> obesity | D14: 8.41 | E14: =IF(Table2[[#This Row],[HBA1C]]<5.7,"normal ",IF(Table2[[#This Row],[HBA1C]]<6.5,"prediabetes",IF(Table2[[#This Row],[HBA1C]]=6.5>6.5,"diabetes "))) -> diabetes | F14: No | G14: No | H14: No | I14: 0 | J14: yes | L14: No | M14: =COUNTIF(J9,"no") -> 0
A15: Id14 | B15: 40.565 | C15: =IF(Table2[[#This Row],[BMI]]<18.5,"under weight ",IF(Table2[[#This Row],[BMI]]<24.9,"normal weight",IF(Table2[[#This Row],[BMI]]<30,"over weight",IF(Table2[[#This Row],[BMI]]>29.9," obesity ")))) -> obesity | D15: 7.02 | E15: =IF(Table2[[#This Row],[HBA1C]]<5.7,"normal ",IF(Table2[[#This Row],[HBA1C]]<6.5,"prediabetes",IF(Table2[[#This Row],[HBA1C]]=6.5>6.5,"diabetes "))) -> diabetes | F15: No | G15: No | H15: No | I15: 0 | J15: yes
A16: Id15 | B16: 36.385 | C16: =IF(Table2[[#This Row],[BMI]]<18.5,"under weight ",IF(Table2[[#This Row],[BMI]]<24.9,"normal weight",IF(Table2[[#This Row],[BMI]]<30,"over weight",IF(Table2[[#This Row],[BMI]]>29.9," obesity ")))) -> obesity | D16: 7.59 | E16: =IF(Table2[[#This Row],[HBA1C]]<5.7,"normal ",IF(Table2[[#This Row],[HBA1C]]<6.5,"prediabetes",IF(Table2[[#This Row],[HBA1C]]=6.5>6.5,"diabetes "))) -> diabetes | F16: yes | G16: No | H16: No | I16: 2 | J16: yes
A17: Id16 | B17: 39.9 | C17: =IF(Table2[[#This Row],[BMI]]<18.5,"under weight ",IF(Table2[[#This Row],[BMI]]<24.9,"normal weight",IF(Table2[[#This Row],[BMI]]<30,"over weight",IF(Table2[[#This Row],[BMI]]>29.9," obesity ")))) -> obesity | D17: 11.32 | E17: =IF(Table2[[#This Row],[HBA1C]]<5.7,"normal ",IF(Table2[[#This Row],[HBA1C]]<6.5,"prediabetes",IF(Table2[[#This Row],[HBA1C]]=6.5>6.5,"diabetes "))) -> diabetes | F17: No | G17: No | H17: No | I17: 0 | J17: yes
A18: Id17 | B18: 33.8 | C18: =IF(Table2[[#This Row],[BMI]]<18.5,"under weight ",IF(Table2[[#This Row],[BMI]]<24.9,"normal weight",IF(Table2[[#This Row],[BMI]]<30,"over weight",IF(Table2[[#This Row],[BMI]]>29.9," obesity ")))) -> obesity | D18: 7.67 | E18: =IF(Table2[[#This Row],[HBA1C]]<5.7,"normal ",IF(Table2[[#This Row],[HBA1C]]<6.5,"prediabetes",IF(Table2[[#This Row],[HBA1C]]=6.5>6.5,"diabetes "))) -> diabetes | F18: No | G18: No | H18: No | I18: 3 | J18: yes
A19: Id18 | B19: 36.765 | C19: =IF(Table2[[#This Row],[BMI]]<18.5,"under weight ",IF(Table2[[#This Row],[BMI]]<24.9,"normal weight",IF(Table2[[#This Row],[BMI]]<30,"over weight",IF(Table2[[#This Row],[BMI]]>29.9," obesity ")))) -> obesity | D19: 7.29 | E19: =IF(Table2[[#This Row],[HBA1C]]<5.7,"normal ",IF(Table2[[#This Row],[HBA1C]]<6.5,"prediabetes",IF(Table2[[#This Row],[HBA1C]]=6.5>6.5,"diabetes "))) -> diabetes | F19: yes | G19: No | H19: Yes | I19: 1 | J19: yes
A20: Id19 | B20: 36.955 | C20: =IF(Table2[[#This Row],[BMI]]<18.5,"under weight ",IF(Table2[[#This Row],[BMI]]<24.9,"normal weight",IF(Table2[[#This Row],[BMI]]<30,"over weight",IF(Table2[[#This Row],[BMI]]>29.9," obesity ")))) -> obesity | D20: 4.72 | E20: =IF(Table2[[#This Row],[HBA1C]]<5.7,"normal ",IF(Table2[[#This Row],[HBA1C]]<6.5,"prediabetes",IF(Table2[[#This Row],[HBA1C]]=6.5>6.5,"diabetes "))) -> normal | F20: yes | G20: No | H20: No | I20: 1 | J20: yes
A21: Id20 | B21: 42.9 | C21: =IF(Table2[[#This Row],[BMI]]<18.5,"under weight ",IF(Table2[[#This Row],[BMI]]<24.9,"normal weight",IF(Table2[[#This Row],[BMI]]<30,"over weight",IF(Table2[[#This Row],[BMI]]>29.9," obesity ")))) -> obesity | D21: 11.41 | E21: =IF(Table2[[#This Row],[HBA1C]]<5.7,"normal ",IF(Table2[[#This Row],[HBA1C]]<6.5,"prediabetes",IF(Table2[[#This Row],[HBA1C]]=6.5>6.5,"diabetes "))) -> diabetes | F21: No | G21: No | H21: No | I21: 0 | J21: yes
A22: Id21 | B22: 36.3 | C22: =IF(Table2[[#This Row],[BMI]]<18.5,"under weight ",IF(Table2[[#This Row],[BMI]]<24.9,"normal weight",IF(Table2[[#This Row],[BMI]]<30,"over weight",IF(Table2[[#This Row],[BMI]]>29.9," obesity ")))) -> obesity | D22: 11.5 | E22: =IF(Table2[[#This Row],[HBA1C]]<5.7,"normal ",IF(Table2[[#This Row],[HBA1C]]<6.5,"prediabetes",IF(Table2[[#This Row],[HBA1C]]=6.5>6.5,"diabetes "))) -> diabetes | F22: yes | G22: No | H22: No | I22: 2 | J22: yes
A23: Id22 | B23: 32.2 | C23: =IF(Table2[[#This Row],[BMI]]<18.5,"under weight ",IF(Table2[[#This Row],[BMI]]<24.9,"normal weight",IF(Table2[[#This Row],[BMI]]<30,"over weight",IF(Table2[[#This Row],[BMI]]>29.9," obesity ")))) -> obesity | D23: 6.22 | E23: =IF(Table2[[#This Row],[HBA1C]]<5.7,"normal ",IF(Table2[[#This Row],[HBA1C]]<6.5,"prediabetes",IF(Table2[[#This Row],[HBA1C]]=6.5>6.5,"diabetes "))) -> prediabetes | F23: yes | G23: No | H23: No | I23: 2 | J23: yes
A24: Id23 | B24: 31.3 | C24: =IF(Table2[[#This Row],[BMI]]<18.5,"under weight ",IF(Table2[[#This Row],[BMI]]<24.9,"normal weight",IF(Table2[[#This Row],[BMI]]<30,"over weight",IF(Table2[[#This Row],[BMI]]>29.9," obesity ")))) -> obesity | D24: 11.38 | E24: =IF(Table2[[#This Row],[HBA1C]]<5.7,"normal ",IF(Table2[[#This Row],[HBA1C]]<6.5,"prediabetes",IF(Table2[[#This Row],[HBA1C]]=6.5>6.5,"diabetes "))) -> diabetes | F24: No | G24: No | H24: No | I24: 3 | J24: yes
A25: Id24 | B25: 41.8 | C25: =IF(Table2[[#This Row],[BMI]]<18.5,"under weight ",IF(Table2[[#This Row],[BMI]]<24.9,"normal weight",IF(Table2[[#This Row],[BMI]]<30,"over weight",IF(Table2[[#This Row],[BMI]]>29.9," obesity ")))) -> obesity | D25: 7.89 | E25: =IF(Table2[[#This Row],[HBA1C]]<5.7,"normal ",IF(Table2[[#This Row],[HBA1C]]<6.5,"prediabetes",IF(Table2[[#This Row],[HBA1C]]=6.5>6.5,"diabetes "))) -> diabetes | F25: yes | G25: No | H25: No | I25: 2 | J25: yes
A26: Id25 | B26: 35.09 | C26: =IF(Table2[[#This Row],[BMI]]<18.5,"under weight ",IF(Table2[[#This Row],[BMI]]<24.9,"normal weight",IF(Table2[[#This Row],[BMI]]<30,"over weight",IF(Table2[[#This Row],[BMI]]>29.9," obesity ")))) -> obesity | D26: 4.38 | E26: =IF(Table2[[#This Row],[HBA1C]]<5.7,"normal ",IF(Table2[[#This Row],[HBA1C]]<6.5,"prediabetes",IF(Table2[[#This Row],[HBA1C]]=6.5>6.5,"diabetes "))) -> normal | F26: yes | G26: No | H26: No | I26: 2 | J26: yes
... A2336: Id2335 | B2336: 17.58 | C2336: =IF(Table2[[#This Row],[BMI]]<18.5,"under weight ",IF(Table2[[#This Row],[BMI]]<24.9,"normal weight",IF(Table2[[#This Row],[BMI]]<30,"over weight",IF(Table2[[#This Row],[BMI]]>29.9," obesity ")))) -> under weight | D2336: 4.51 | E2336: =IF(Table2[[#This Row],[HBA1C]]<5.7,"normal ",IF(Table2[[#This Row],[HBA1C]]<6.5,"prediabetes",IF(Table2[[#This Row],[HBA1C]]=6.5>6.5,"diabetes "))) -> normal | F2336: No | G2336: No | H2336: No | I2336: 1 | J2336: No

Sheet Hospitalisation Details
A1: Customer ID | B1: year | C1: month | D1: date | E1: DOB | F1: Age | G1: children | H1: charges | I1: Hospital tier | J1: City tier | K1: State ID
A2: Id2335 | B2: 1992 | C2: Jul | D2: 9 | E2: =Table1[[#This Row],[date]]&" "&Table1[[#This Row],[month]]&" "&Table1[[#This Row],[year]] -> 9 Jul 1992 | F2: =DATEDIF(Table1[[#This Row],[DOB]],"8-6-2023","y") -> 30 | G2: 0 | H2: 563.84 | I2: tier - 2 | J2: tier - 3 | K2: R1013
A3: Id2334 | B3: 1992 | C3: Nov | D3: 30 | E3: =Table1[[#This Row],[date]]&" "&Table1[[#This Row],[month]]&" "&Table1[[#This Row],[year]] -> 30 Nov 1992 | F3: =DATEDIF(Table1[[#This Row],[DOB]],"8-6-2023","y") -> 30 | G3: 0 | H3: 570.62 | I3: tier - 2 | J3: tier - 1 | K3: R1013 | N3: =COUNTIF(A:A,"?") -> 6
A4: Id2333 | B4: 1993 | C4: Jun | D4: 30 | E4: =Table1[[#This Row],[date]]&" "&Table1[[#This Row],[month]]&" "&Table1[[#This Row],[year]] -> 30 Jun 1993 | F4: =DATEDIF(Table1[[#This Row],[DOB]],"8-6-2023","y") -> 29 | G4: 0 | H4: 600 | I4: tier - 2 | J4: tier - 1 | K4: R1013 | N4: =COUNTIF(B:B,"?") -> 0
A5: Id2332 | B5: 1992 | C5: Sep | D5: 13 | E5: =Table1[[#This Row],[date]]&" "&Table1[[#This Row],[month]]&" "&Table1[[#This Row],[year]] -> 13 Sep 1992 | F5: =DATEDIF(Table1[[#This Row],[DOB]],"8-6-2023","y") -> 30 | G5: 0 | H5: 604.54 | I5: tier - 3 | J5: tier - 3 | K5: R1013 | N5: =COUNTIF(C:C,"?") -> 0
A6: Id2331 | B6: 1998 | C6: Jul | D6: 27 | E6: =Table1[[#This Row],[date]]&" "&Table1[[#This Row],[month]]&" "&Table1[[#This Row],[year]] -> 27 Jul 1998 | F6: =DATEDIF(Table1[[#This Row],[DOB]],"8-6-2023","y") -> 24 | G6: 0 | H6: 637.26 | I6: tier - 3 | J6: tier - 3 | K6: R1013 | N6: =COUNTIF(D:D,"?") -> 0
A7: Id2330 | B7: 2001 | C7: Nov | D7: 20 | E7: =Table1[[#This Row],[date]]&" "&Table1[[#This Row],[month]]&" "&Table1[[#This Row],[year]] -> 20 Nov 2001 | F7: =DATEDIF(Table1[[#This Row],[DOB]],"8-6-2023","y") -> 21 | G7: 0 | H7: 646.14 | I7: tier - 3 | J7: tier - 3 | K7: R1012 | N7: =COUNTIF(D:D,"?") -> 0
A8: Id2329 | B8: 1993 | C8: Jun | D8: 1 | E8: =Table1[[#This Row],[date]]&" "&Table1[[#This Row],[month]]&" "&Table1[[#This Row],[year]] -> 1 Jun 1993 | F8: =DATEDIF(Table1[[#This Row],[DOB]],"8-6-2023","y") -> 30 | G8: 0 | H8: 650 | I8: tier - 3 | J8: tier - 3 | K8: R1013 | N8: =COUNTIF(F:F,"?") -> 0
A9: Id2328 | B9: 1995 | C9: Jul | D9: 4 | E9: =Table1[[#This Row],[date]]&" "&Table1[[#This Row],[month]]&" "&Table1[[#This Row],[year]] -> 4 Jul 1995 | F9: =DATEDIF(Table1[[#This Row],[DOB]],"8-6-2023","y") -> 27 | G9: 0 | H9: 650 | I9: tier - 3 | J9: tier - 3 | K9: R1013 | N9: =COUNTIF(Table1[children],"?") -> 0
A10: Id2327 | B10: 2002 | C10: Nov | D10: 29 | E10: =Table1[[#This Row],[date]]&" "&Table1[[#This Row],[month]]&" "&Table1[[#This Row],[year]] -> 29 Nov 2002 | F10: =DATEDIF(Table1[[#This Row],[DOB]],"8-6-2023","y") -> 20 | G10: 0 | H10: 668 | I10: tier - 3 | J10: tier - 2 | K10: R1012 | N10: =COUNTIF(I:I,"?") -> 0
A11: Id2326 | B11: 1997 | C11: Nov | D11: 9 | E11: =Table1[[#This Row],[date]]&" "&Table1[[#This Row],[month]]&" "&Table1[[#This Row],[year]] -> 9 Nov 1997 | F11: =DATEDIF(Table1[[#This Row],[DOB]],"8-6-2023","y") -> 25 | G11: 0 | H11: 670 | I11: tier - 3 | J11: tier - 3 | K11: R1013 | N11: =COUNTIF(Table1[charges],"?") -> 0
A12: Id2325 | B12: 2001 | C12: Sep | D12: 12 | E12: =Table1[[#This Row],[date]]&" "&Table1[[#This Row],[month]]&" "&Table1[[#This Row],[year]] -> 12 Sep 2001 | F12: =DATEDIF(Table1[[#This Row],[DOB]],"8-6-2023","y") -> 21 | G12: 0 | H12: 687.54 | I12: tier - 3 | J12: tier - 2 | K12: R1013 | N12: =COUNTIF(Table1[City tier],"?") -> 0
A13: Id2324 | B13: 1999 | C13: Dec | D13: 26 | E13: =Table1[[#This Row],[date]]&" "&Table1[[#This Row],[month]]&" "&Table1[[#This Row],[year]] -> 26 Dec 1999 | F13: =DATEDIF(Table1[[#This Row],[DOB]],"8-6-2023","y") -> 23 | G13: 0 | H13: 700 | I13: tier - 2 | J13: tier - 3 | K13: R1013 | N13: =COUNTIF(Table1[State ID],"?") -> 0
A14: Id2323 | B14: 1999 | C14: Dec | D14: 14 | E14: =Table1[[#This Row],[date]]&" "&Table1[[#This Row],[month]]&" "&Table1[[#This Row],[year]] -> 14 Dec 1999 | F14: =DATEDIF(Table1[[#This Row],[DOB]],"8-6-2023","y") -> 23 | G14: 0 | H14: 722.99 | I14: tier - 3 | J14: tier - 1 | K14: R1013 | M14: Total count of "?" | N14: =SUM(N3:N13) -> 6
A15: Id2322 | B15: 2002 | C15: sep | D15: 19 | E15: =Table1[[#This Row],[date]]&" "&Table1[[#This Row],[month]]&" "&Table1[[#This Row],[year]] -> 19 sep 2002 | F15: =DATEDIF(Table1[[#This Row],[DOB]],"8-6-2023","y") -> 20 | G15: 0 | H15: 750 | I15: tier - 3 | J15: tier - 1 | K15: R1012
A16: Id2321 | B16: 1993 | C16: Aug | D16: 9 | E16: =Table1[[#This Row],[date]]&" "&Table1[[#This Row],[month]]&" "&Table1[[#This Row],[year]] -> 9 Aug 1993 | F16: =DATEDIF(Table1[[#This Row],[DOB]],"8-6-2023","y") -> 29 | G16: 0 | H16: 760 | I16: tier - 3 | J16: tier - 1 | K16: R1013
A17: Id2320 | B17: 1996 | C17: Oct | D17: 22 | E17: =Table1[[#This Row],[date]]&" "&Table1[[#This Row],[month]]&" "&Table1[[#This Row],[year]] -> 22 Oct 1996 | F17: =DATEDIF(Table1[[#This Row],[DOB]],"8-6-2023","y") -> 26 | G17: 0 | H17: 760 | I17: tier - 3 | J17: tier - 3 | K17: R1013 | M17: Average | N17: =AVERAGE(Table1[year]) -> 1982.8417
A18: Id2319 | B18: 1993 | C18: Jun | D18: 28 | E18: =Table1[[#This Row],[date]]&" "&Table1[[#This Row],[month]]&" "&Table1[[#This Row],[year]] -> 28 Jun 1993 | F18: =DATEDIF(Table1[[#This Row],[DOB]],"8-6-2023","y") -> 29 | G18: 0 | H18: 770 | I18: tier - 3 | J18: tier - 3 | K18: R1013 | M18: Frequent - hospital tier | N18: =COUNTIF(Table1[Hospital tier],"tier - 3") -> 694 | O18: =COUNTIF(Table1[Hospital tier],"tier - 2") -> 1340 | P18: =COUNTIF(Table1[Hospital tier],"tier - 1") -> 309
A19: Id2318 | B19: 1996 | C19: sep | D19: 18 | E19: =Table1[[#This Row],[date]]&" "&Table1[[#This Row],[month]]&" "&Table1[[#This Row],[year]] -> 18 sep 1996 | F19: =DATEDIF(Table1[[#This Row],[DOB]],"8-6-2023","y") -> 26 | G19: 0 | H19: 770.38 | I19: tier - 3 | J19: tier - 2 | K19: R1012 | M19: City tier | N19: =COUNTIF(Table1[City tier],"tier - 1") -> 734 | O19: =COUNTIF(Table1[City tier],"tier - 2") -> 813 | P19: =COUNTIF(Table1[City tier],"tier - 3") -> 796
A20: Id2317 | B20: 1995 | C20: Dec | D20: 7 | E20: =Table1[[#This Row],[date]]&" "&Table1[[#This Row],[month]]&" "&Table1[[#This Row],[year]] -> 7 Dec 1995 | F20: =DATEDIF(Table1[[#This Row],[DOB]],"8-6-2023","y") -> 27 | G20: 0 | H20: 773.54 | I20: tier - 3 | J20: tier - 2 | K20: R1013
A21: Id2316 | B21: 2004 | C21: Oct | D21: 7 | E21: =Table1[[#This Row],[date]]&" "&Table1[[#This Row],[month]]&" "&Table1[[#This Row],[year]] -> 7 Oct 2004 | F21: =DATEDIF(Table1[[#This Row],[DOB]],"8-6-2023","y") -> 18 | G21: 0 | H21: 830.52 | I21: tier - 3 | J21: tier - 2 | K21: R1011
A22: Id2315 | B22: 2000 | C22: Nov | D22: 18 | E22: =Table1[[#This Row],[date]]&" "&Table1[[#This Row],[month]]&" "&Table1[[#This Row],[year]] -> 18 Nov 2000 | F22: =DATEDIF(Table1[[#This Row],[DOB]],"8-6-2023","y") -> 22 | G22: 0 | H22: 865.41 | I22: tier - 3 | J22: tier - 1 | K22: R1013
A23: Id2314 | B23: 1993 | C23: Nov | D23: 27 | E23: =Table1[[#This Row],[date]]&" "&Table1[[#This Row],[month]]&" "&Table1[[#This Row],[year]] -> 27 Nov 1993 | F23: =DATEDIF(Table1[[#This Row],[DOB]],"8-6-2023","y") -> 29 | G23: 0 | H23: 896.21 | I23: tier - 3 | J23: tier - 1 | K23: R1013
A24: Id2313 | B24: 1994 | C24: Oct | D24: 30 | E24: =Table1[[#This Row],[date]]&" "&Table1[[#This Row],[month]]&" "&Table1[[#This Row],[year]] -> 30 Oct 1994 | F24: =DATEDIF(Table1[[#This Row],[DOB]],"8-6-2023","y") -> 28 | G24: 0 | H24: 915.07 | I24: tier - 3 | J24: tier - 1 | K24: R1013
A25: Id2312 | B25: 1995 | C25: Oct | D25: 28 | E25: =Table1[[#This Row],[date]]&" "&Table1[[#This Row],[month]]&" "&Table1[[#This Row],[year]] -> 28 Oct 1995 | F25: =DATEDIF(Table1[[#This Row],[DOB]],"8-6-2023","y") -> 27 | G25: 0 | H25: 928.59 | I25: tier - 3 | J25: tier - 1 | K25: R1013
A26: Id2311 | B26: 2001 | C26: Aug | D26: 19 | E26: =Table1[[#This Row],[date]]&" "&Table1[[#This Row],[month]]&" "&Table1[[#This Row],[year]] -> 19 Aug 2001 | F26: =DATEDIF(Table1[[#This Row],[DOB]],"8-6-2023","y") -> 21 | G26: 0 | H26: 964.71 | I26: tier - 3 | J26: tier - 2 | K26: R1013
A27: Id2310 | B27: 1994 | C27: Nov | D27: 22 | E27: =Table1[[#This Row],[date]]&" "&Table1[[#This Row],[month]]&" "&Table1[[#This Row],[year]] -> 22 Nov 1994 | F27: =DATEDIF(Table1[[#This Row],[DOB]],"8-6-2023","y") -> 28 | G27: 0 | H27: 1006.65 | I27: tier - 3 | J27: tier - 2 | K27: R1013
A28: Id2309 | B28: 2000 | C28: Oct | D28: 9 | E28: =Table1[[#This Row],[date]]&" "&Table1[[#This Row],[month]]&" "&Table1[[#This Row],[year]] -> 9 Oct 2000 | F28: =DATEDIF(Table1[[#This Row],[DOB]],"8-6-2023","y") -> 22 | G28: 0 | H28: 1012 | I28: tier - 3 | J28: tier - 2 | K28: R1013
A29: Id2308 | B29: 1999 | C29: Aug | D29: 5 | E29: =Table1[[#This Row],[date]]&" "&Table1[[#This Row],[month]]&" "&Table1[[#This Row],[year]] -> 5 Aug 1999 | F29: =DATEDIF(Table1[[#This Row],[DOB]],"8-6-2023","y") -> 23 | G29: 0 | H29: 1019 | I29: tier - 3 | J29: tier - 2 | K29: R1013
A30: Id2307 | B30: 1995 | C30: Oct | D30: 5 | E30: =Table1[[#This Row],[date]]&" "&Table1[[#This Row],[month]]&" "&Table1[[#This Row],[year]] -> 5 Oct 1995 | F30: =DATEDIF(Table1[[#This Row],[DOB]],"8-6-2023","y") -> 27 | G30: 0 | H30: 1033.74 | I30: tier - 3 | J30: tier - 1 | K30: R1013
A31: Id2306 | B31: 1994 | C31: Nov | D31: 17 | E31: =Table1[[#This Row],[date]]&" "&Table1[[#This Row],[month]]&" "&Table1[[#This Row],[year]] -> 17 Nov 1994 | F31: =DATEDIF(Table1[[#This Row],[DOB]],"8-6-2023","y") -> 28 | G31: 0 | H31: 1044 | I31: tier - 3 | J31: tier - 2 | K31: R1013
... A2344: Id1 | B2344: 1968 | C2344: Oct | D2344: 12 | E2344: =Table1[[#This Row],[date]]&" "&Table1[[#This Row],[month]]&" "&Table1[[#This Row],[year]] -> 12 Oct 1968 | F2344: =DATEDIF(Table1[[#This Row],[DOB]],"8-6-2023","y") -> 54 | G2344: 0 | H2344: 63770.43 | I2344: tier - 1 | J2344: tier - 3 | K2344: R1013

Sheet Healthcare 
A1: Customer ID | B1: Name | C1: Weight | D1: Weight status | E1: HBA1C | F1: Diabetes status | G1: Heart Issues | H1: Any Transplants | I1: Cancer history | J1: NumberOfMajorSurgeries | K1: smoker | L1: DOB | M1: Age | N1: charges | O1: Hospital tier | P1: City tier | Q1: State ID
A2: Id1 | B2: =VLOOKUP(Table3[[#This Row],[Customer ID]],'Customer name 1'!1:$1048576,4,FALSE()) -> Ms. Kelly | C2: =VLOOKUP(Table3[[#This Row],[Customer ID]],'Medical Examinations'!$1:$1048576,2,FALSE()) -> 47.41 | D2: =VLOOKUP(Table3[[#This Row],[Customer ID]],'Medical Examinations'!$1:$1048576,3,FALSE()) -> obesity | E2: =VLOOKUP(Table3[[#This Row],[Customer ID]],'Medical Examinations'!$1:$1048576,4,FALSE()) -> 7.47 | F2: =VLOOKUP(Table3[[#This Row],[Customer ID]],'Medical Examinations'!$1:$1048576,5,FALSE()) -> diabetes | G2: =VLOOKUP(Table3[[#This Row],[Customer ID]],'Medical Examinations'!$1:$1048576,6,FALSE()) -> No | H2: =VLOOKUP(Table3[[#This Row],[Customer ID]],'Medical Examinations'!$1:$1048576,7,FALSE()) -> No | I2: =VLOOKUP(Table3[[#This Row],[Customer ID]],'Medical Examinations'!$1:$1048576,8,FALSE()) -> No | J2: =VLOOKUP(Table3[[#This Row],[Customer ID]],'Medical Examinations'!$1:$1048576,9,FALSE()) -> 0 | K2: =VLOOKUP(Table3[[#This Row],[Customer ID]],'Medical Examinations'!$1:$1048576,10,FALSE()) -> yes | L2: =VLOOKUP(Table3[[#This Row],[Customer ID]],'Hospitalisation Details'!1:$1048576,5,FALSE()) -> 12 Oct 1968 | M2: =VLOOKUP(Table3[[#This Row],[Customer ID]],'Hospitalisation Details'!1:$1048576,6,FALSE()) -> 54 | N2: =VLOOKUP(Table3[[#This Row],[Customer ID]],'Hospitalisation Details'!1:$1048576,8,FALSE()) -> 63770.43 | O2: =VLOOKUP(Table3[[#This Row],[Customer ID]],'Hospitalisation Details'!1:$1048576,9,FALSE()) -> tier - 1 | P2: =VLOOKUP(Table3[[#This Row],[Customer ID]],'Hospitalisation Details'!1:$1048576,10,FALSE()) -> tier - 3 | Q2: =VLOOKUP(Table3[[#This Row],[Customer ID]],'Hospitalisation Details'!1:$1048576,11,FALSE()) -> R1013
A3: Id2 | B3: =VLOOKUP(Table3[[#This Row],[Customer ID]],'Customer name 1'!2:$1048576,4,FALSE()) -> Mr. Matthew | C3: =VLOOKUP(Table3[[#This Row],[Customer ID]],'Medical Examinations'!$1:$1048576,2,FALSE()) -> 30.36 | D3: =VLOOKUP(Table3[[#This Row],[Customer ID]],'Medical Examinations'!$1:$1048576,3,FALSE()) -> obesity | E3: =VLOOKUP(Table3[[#This Row],[Customer ID]],'Medical Examinations'!$1:$1048576,4,FALSE()) -> 5.77 | F3: =VLOOKUP(Table3[[#This Row],[Customer ID]],'Medical Examinations'!$1:$1048576,5,FALSE()) -> prediabetes | G3: =VLOOKUP(Table3[[#This Row],[Customer ID]],'Medical Examinations'!$1:$1048576,6,FALSE()) -> No | H3: =VLOOKUP(Table3[[#This Row],[Customer ID]],'Medical Examinations'!$1:$1048576,7,FALSE()) -> No | I3: =VLOOKUP(Table3[[#This Row],[Customer ID]],'Medical Examinations'!$1:$1048576,8,FALSE()) -> No | J3: =VLOOKUP(Table3[[#This Row],[Customer ID]],'Medical Examinations'!$1:$1048576,9,FALSE()) -> 0 | K3: =VLOOKUP(Table3[[#This Row],[Customer ID]],'Medical Examinations'!$1:$1048576,10,FALSE()) -> yes | L3: =VLOOKUP(Table3[[#This Row],[Customer ID]],'Hospitalisation Details'!2:$1048576,5,FALSE()) -> 8 Jun 1977 | M3: =VLOOKUP(Table3[[#This Row],[Customer ID]],'Hospitalisation Details'!2:$1048576,6,FALSE()) -> 46 | N3: =VLOOKUP(Table3[[#This Row],[Customer ID]],'Hospitalisation Details'!2:$1048576,8,FALSE()) -> 62592.87 | O3: =VLOOKUP(Table3[[#This Row],[Customer ID]],'Hospitalisation Details'!2:$1048576,9,FALSE()) -> tier - 2 | P3: =VLOOKUP(Table3[[#This Row],[Customer ID]],'Hospitalisation Details'!2:$1048576,10,FALSE()) -> tier - 3 | Q3: =VLOOKUP(Table3[[#This Row],[Customer ID]],'Hospitalisation Details'!2:$1048576,11,FALSE()) -> R1013
A4: Id3 | B4: =VLOOKUP(Table3[[#This Row],[Customer ID]],'Customer name 1'!3:$1048576,4,FALSE()) -> Mr. Phil | C4: =VLOOKUP(Table3[[#This Row],[Customer ID]],'Medical Examinations'!$1:$1048576,2,FALSE()) -> 34.485 | D4: =VLOOKUP(Table3[[#This Row],[Customer ID]],'Medical Examinations'!$1:$1048576,3,FALSE()) -> obesity | E4: =VLOOKUP(Table3[[#This Row],[Customer ID]],'Medical Examinations'!$1:$1048576,4,FALSE()) -> 11.87 | F4: =VLOOKUP(Table3[[#This Row],[Customer ID]],'Medical Examinations'!$1:$1048576,5,FALSE()) -> diabetes | G4: =VLOOKUP(Table3[[#This Row],[Customer ID]],'Medical Examinations'!$1:$1048576,6,FALSE()) -> yes | H4: =VLOOKUP(Table3[[#This Row],[Customer ID]],'Medical Examinations'!$1:$1048576,7,FALSE()) -> No | I4: =VLOOKUP(Table3[[#This Row],[Customer ID]],'Medical Examinations'!$1:$1048576,8,FALSE()) -> No | J4: =VLOOKUP(Table3[[#This Row],[Customer ID]],'Medical Examinations'!$1:$1048576,9,FALSE()) -> 2 | K4: =VLOOKUP(Table3[[#This Row],[Customer ID]],'Medical Examinations'!$1:$1048576,10,FALSE()) -> yes | L4: =VLOOKUP(Table3[[#This Row],[Customer ID]],'Hospitalisation Details'!3:$1048576,5,FALSE()) -> 11 sep 1970 | M4: =VLOOKUP(Table3[[#This Row],[Customer ID]],'Hospitalisation Details'!3:$1048576,6,FALSE()) -> 52 | N4: =VLOOKUP(Table3[[#This Row],[Customer ID]],'Hospitalisation Details'!3:$1048576,8,FALSE()) -> 60021.4 | O4: =VLOOKUP(Table3[[#This Row],[Customer ID]],'Hospitalisation Details'!3:$1048576,9,FALSE()) -> tier - 1 | P4: =VLOOKUP(Table3[[#This Row],[Customer ID]],'Hospitalisation Details'!3:$1048576,10,FALSE()) -> tier - 1 | Q4: =VLOOKUP(Table3[[#This Row],[Customer ID]],'Hospitalisation Details'!3:$1048576,11,FALSE()) -> R1012
A5: Id4 | B5: =VLOOKUP(Table3[[#This Row],[Customer ID]],'Customer name 1'!4:$1048576,4,FALSE()) -> Ms. Kelsey | C5: =VLOOKUP(Table3[[#This Row],[Customer ID]],'Medical Examinations'!$1:$1048576,2,FALSE()) -> 38.095 | D5: =VLOOKUP(Table3[[#This Row],[Customer ID]],'Medical Examinations'!$1:$1048576,3,FALSE()) -> obesity | E5: =VLOOKUP(Table3[[#This Row],[Customer ID]],'Medical Examinations'!$1:$1048576,4,FALSE()) -> 6.05 | F5: =VLOOKUP(Table3[[#This Row],[Customer ID]],'Medical Examinations'!$1:$1048576,5,FALSE()) -> prediabetes | G5: =VLOOKUP(Table3[[#This Row],[Customer ID]],'Medical Examinations'!$1:$1048576,6,FALSE()) -> No | H5: =VLOOKUP(Table3[[#This Row],[Customer ID]],'Medical Examinations'!$1:$1048576,7,FALSE()) -> No | I5: =VLOOKUP(Table3[[#This Row],[Customer ID]],'Medical Examinations'!$1:$1048576,8,FALSE()) -> No | J5: =VLOOKUP(Table3[[#This Row],[Customer ID]],'Medical Examinations'!$1:$1048576,9,FALSE()) -> 0 | K5: =VLOOKUP(Table3[[#This Row],[Customer ID]],'Medical Examinations'!$1:$1048576,10,FALSE()) -> yes | L5: =VLOOKUP(Table3[[#This Row],[Customer ID]],'Hospitalisation Details'!4:$1048576,5,FALSE()) -> 6 Jun 1991 | M5: =VLOOKUP(Table3[[#This Row],[Customer ID]],'Hospitalisation Details'!4:$1048576,6,FALSE()) -> 32 | N5: =VLOOKUP(Table3[[#This Row],[Customer ID]],'Hospitalisation Details'!4:$1048576,8,FALSE()) -> 58571.07 | O5: =VLOOKUP(Table3[[#This Row],[Customer ID]],'Hospitalisation Details'!4:$1048576,9,FALSE()) -> tier - 1 | P5: =VLOOKUP(Table3[[#This Row],[Customer ID]],'Hospitalisation Details'!4:$1048576,10,FALSE()) -> tier - 3 | Q5: =VLOOKUP(Table3[[#This Row],[Customer ID]],'Hospitalisation Details'!4:$1048576,11,FALSE()) -> R1024
A6: Id5 | B6: =VLOOKUP(Table3[[#This Row],[Customer ID]],'Customer name 1'!5:$1048576,4,FALSE()) -> Ms. Kristyn | C6: =VLOOKUP(Table3[[#This Row],[Customer ID]],'Medical Examinations'!$1:$1048576,2,FALSE()) -> 35.53 | D6: =VLOOKUP(Table3[[#This Row],[Customer ID]],'Medical Examinations'!$1:$1048576,3,FALSE()) -> obesity | E6: =VLOOKUP(Table3[[#This Row],[Customer ID]],'Medical Examinations'!$1:$1048576,4,FALSE()) -> 5.45 | F6: =VLOOKUP(Table3[[#This Row],[Customer ID]],'Medical Examinations'!$1:$1048576,5,FALSE()) -> normal | G6: =VLOOKUP(Table3[[#This Row],[Customer ID]],'Medical Examinations'!$1:$1048576,6,FALSE()) -> No | H6: =VLOOKUP(Table3[[#This Row],[Customer ID]],'Medical Examinations'!$1:$1048576,7,FALSE()) -> No | I6: =VLOOKUP(Table3[[#This Row],[Customer ID]],'Medical Examinations'!$1:$1048576,8,FALSE()) -> No | J6: =VLOOKUP(Table3[[#This Row],[Customer ID]],'Medical Examinations'!$1:$1048576,9,FALSE()) -> 0 | K6: =VLOOKUP(Table3[[#This Row],[Customer ID]],'Medical Examinations'!$1:$1048576,10,FALSE()) -> yes | L6: =VLOOKUP(Table3[[#This Row],[Customer ID]],'Hospitalisation Details'!5:$1048576,5,FALSE()) -> 19 Jun 1989 | M6: =VLOOKUP(Table3[[#This Row],[Customer ID]],'Hospitalisation Details'!5:$1048576,6,FALSE()) -> 33 | N6: =VLOOKUP(Table3[[#This Row],[Customer ID]],'Hospitalisation Details'!5:$1048576,8,FALSE()) -> 55135.4 | O6: =VLOOKUP(Table3[[#This Row],[Customer ID]],'Hospitalisation Details'!5:$1048576,9,FALSE()) -> tier - 1 | P6: =VLOOKUP(Table3[[#This Row],[Customer ID]],'Hospitalisation Details'!5:$1048576,10,FALSE()) -> tier - 2 | Q6: =VLOOKUP(Table3[[#This Row],[Customer ID]],'Hospitalisation Details'!5:$1048576,11,FALSE()) -> R1012
A7: Id6 | B7: =VLOOKUP(Table3[[#This Row],[Customer ID]],'Customer name 1'!6:$1048576,4,FALSE()) -> Mr. Russell | C7: =VLOOKUP(Table3[[#This Row],[Customer ID]],'Medical Examinations'!$1:$1048576,2,FALSE()) -> 32.8 | D7: =VLOOKUP(Table3[[#This Row],[Customer ID]],'Medical Examinations'!$1:$1048576,3,FALSE()) -> obesity | E7: =VLOOKUP(Table3[[#This Row],[Customer ID]],'Medical Examinations'!$1:$1048576,4,FALSE()) -> 6.59 | F7: =VLOOKUP(Table3[[#This Row],[Customer ID]],'Medical Examinations'!$1:$1048576,5,FALSE()) -> diabetes | G7: =VLOOKUP(Table3[[#This Row],[Customer ID]],'Medical Examinations'!$1:$1048576,6,FALSE()) -> No | H7: =VLOOKUP(Table3[[#This Row],[Customer ID]],'Medical Examinations'!$1:$1048576,7,FALSE()) -> No | I7: =VLOOKUP(Table3[[#This Row],[Customer ID]],'Medical Examinations'!$1:$1048576,8,FALSE()) -> No | J7: =VLOOKUP(Table3[[#This Row],[Customer ID]],'Medical Examinations'!$1:$1048576,9,FALSE()) -> 0 | K7: =VLOOKUP(Table3[[#This Row],[Customer ID]],'Medical Examinations'!$1:$1048576,10,FALSE()) -> yes | L7: =VLOOKUP(Table3[[#This Row],[Customer ID]],'Hospitalisation Details'!6:$1048576,5,FALSE()) -> 4 Aug 1962 | M7: =VLOOKUP(Table3[[#This Row],[Customer ID]],'Hospitalisation Details'!6:$1048576,6,FALSE()) -> 60 | N7: =VLOOKUP(Table3[[#This Row],[Customer ID]],'Hospitalisation Details'!6:$1048576,8,FALSE()) -> 52590.83 | O7: =VLOOKUP(Table3[[#This Row],[Customer ID]],'Hospitalisation Details'!6:$1048576,9,FALSE()) -> tier - 1 | P7: =VLOOKUP(Table3[[#This Row],[Customer ID]],'Hospitalisation Details'!6:$1048576,10,FALSE()) -> tier - 3 | Q7: =VLOOKUP(Table3[[#This Row],[Customer ID]],'Hospitalisation Details'!6:$1048576,11,FALSE()) -> R1011
A8: Id7 | B8: =VLOOKUP(Table3[[#This Row],[Customer ID]],'Customer name 1'!7:$1048576,4,FALSE()) -> Mr. Scott | C8: =VLOOKUP(Table3[[#This Row],[Customer ID]],'Medical Examinations'!$1:$1048576,2,FALSE()) -> 36.4 | D8: =VLOOKUP(Table3[[#This Row],[Customer ID]],'Medical Examinations'!$1:$1048576,3,FALSE()) -> obesity | E8: =VLOOKUP(Table3[[#This Row],[Customer ID]],'Medical Examinations'!$1:$1048576,4,FALSE()) -> 6.07 | F8: =VLOOKUP(Table3[[#This Row],[Customer ID]],'Medical Examinations'!$1:$1048576,5,FALSE()) -> prediabetes | G8: =VLOOKUP(Table3[[#This Row],[Customer ID]],'Medical Examinations'!$1:$1048576,6,FALSE()) -> No | H8: =VLOOKUP(Table3[[#This Row],[Customer ID]],'Medical Examinations'!$1:$1048576,7,FALSE()) -> No | I8: =VLOOKUP(Table3[[#This Row],[Customer ID]],'Medical Examinations'!$1:$1048576,8,FALSE()) -> No | J8: =VLOOKUP(Table3[[#This Row],[Customer ID]],'Medical Examinations'!$1:$1048576,9,FALSE()) -> 0 | K8: =VLOOKUP(Table3[[#This Row],[Customer ID]],'Medical Examinations'!$1:$1048576,10,FALSE()) -> yes | L8: =VLOOKUP(Table3[[#This Row],[Customer ID]],'Hospitalisation Details'!7:$1048576,5,FALSE()) -> 27 Oct 1994 | M8: =VLOOKUP(Table3[[#This Row],[Customer ID]],'Hospitalisation Details'!7:$1048576,6,FALSE()) -> 28 | N8: =VLOOKUP(Table3[[#This Row],[Customer ID]],'Hospitalisation Details'!7:$1048576,8,FALSE()) -> 51194.56 | O8: =VLOOKUP(Table3[[#This Row],[Customer ID]],'Hospitalisation Details'!7:$1048576,9,FALSE()) -> tier - 1 | P8: =VLOOKUP(Table3[[#This Row],[Customer ID]],'Hospitalisation Details'!7:$1048576,10,FALSE()) -> tier - 3 | Q8: =VLOOKUP(Table3[[#This Row],[Customer ID]],'Hospitalisation Details'!7:$1048576,11,FALSE()) -> R1011
A9: Id8 | B9: =VLOOKUP(Table3[[#This Row],[Customer ID]],'Customer name 1'!8:$1048576,4,FALSE()) -> Mr. Stephen | C9: =VLOOKUP(Table3[[#This Row],[Customer ID]],'Medical Examinations'!$1:$1048576,2,FALSE()) -> 36.96 | D9: =VLOOKUP(Table3[[#This Row],[Customer ID]],'Medical Examinations'!$1:$1048576,3,FALSE()) -> obesity | E9: =VLOOKUP(Table3[[#This Row],[Customer ID]],'Medical Examinations'!$1:$1048576,4,FALSE()) -> 7.93 | F9: =VLOOKUP(Table3[[#This Row],[Customer ID]],'Medical Examinations'!$1:$1048576,5,FALSE()) -> diabetes | G9: =VLOOKUP(Table3[[#This Row],[Customer ID]],'Medical Examinations'!$1:$1048576,6,FALSE()) -> No | H9: =VLOOKUP(Table3[[#This Row],[Customer ID]],'Medical Examinations'!$1:$1048576,7,FALSE()) -> No | I9: =VLOOKUP(Table3[[#This Row],[Customer ID]],'Medical Examinations'!$1:$1048576,8,FALSE()) -> No | J9: =VLOOKUP(Table3[[#This Row],[Customer ID]],'Medical Examinations'!$1:$1048576,9,FALSE()) -> 3 | K9: =VLOOKUP(Table3[[#This Row],[Customer ID]],'Medical Examinations'!$1:$1048576,10,FALSE()) -> yes | L9: =VLOOKUP(Table3[[#This Row],[Customer ID]],'Hospitalisation Details'!8:$1048576,5,FALSE()) -> 27 Jun 1958 | M9: =VLOOKUP(Table3[[#This Row],[Customer ID]],'Hospitalisation Details'!8:$1048576,6,FALSE()) -> 64 | N9: =VLOOKUP(Table3[[#This Row],[Customer ID]],'Hospitalisation Details'!8:$1048576,8,FALSE()) -> 49577.66 | O9: =VLOOKUP(Table3[[#This Row],[Customer ID]],'Hospitalisation Details'!8:$1048576,9,FALSE()) -> tier - 2 | P9: =VLOOKUP(Table3[[#This Row],[Customer ID]],'Hospitalisation Details'!8:$1048576,10,FALSE()) -> tier - 2 | Q9: =VLOOKUP(Table3[[#This Row],[Customer ID]],'Hospitalisation Details'!8:$1048576,11,FALSE()) -> R1013
A10: Id9 | B10: =VLOOKUP(Table3[[#This Row],[Customer ID]],'Customer name 1'!9:$1048576,4,FALSE()) -> Mr. Patrick | C10: =VLOOKUP(Table3[[#This Row],[Customer ID]],'Medical Examinations'!$1:$1048576,2,FALSE()) -> 41.14 | D10: =VLOOKUP(Table3[[#This Row],[Customer ID]],'Medical Examinations'!$1:$1048576,3,FALSE()) -> obesity | E10: =VLOOKUP(Table3[[#This Row],[Customer ID]],'Medical Examinations'!$1:$1048576,4,FALSE()) -> 9.58 | F10: =VLOOKUP(Table3[[#This Row],[Customer ID]],'Medical Examinations'!$1:$1048576,5,FALSE()) -> diabetes | G10: =VLOOKUP(Table3[[#This Row],[Customer ID]],'Medical Examinations'!$1:$1048576,6,FALSE()) -> yes | H10: =VLOOKUP(Table3[[#This Row],[Customer ID]],'Medical Examinations'!$1:$1048576,7,FALSE()) -> No | I10: =VLOOKUP(Table3[[#This Row],[Customer ID]],'Medical Examinations'!$1:$1048576,8,FALSE()) -> Yes | J10: =VLOOKUP(Table3[[#This Row],[Customer ID]],'Medical Examinations'!$1:$1048576,9,FALSE()) -> 1 | K10: =VLOOKUP(Table3[[#This Row],[Customer ID]],'Medical Examinations'!$1:$1048576,10,FALSE()) -> yes | L10: =VLOOKUP(Table3[[#This Row],[Customer ID]],'Hospitalisation Details'!9:$1048576,5,FALSE()) -> 4 Sep 1963 | M10: =VLOOKUP(Table3[[#This Row],[Customer ID]],'Hospitalisation Details'!9:$1048576,6,FALSE()) -> 59 | N10: =VLOOKUP(Table3[[#This Row],[Customer ID]],'Hospitalisation Details'!9:$1048576,8,FALSE()) -> 48970.25 | O10: =VLOOKUP(Table3[[#This Row],[Customer ID]],'Hospitalisation Details'!9:$1048576,9,FALSE()) -> tier - 1 | P10: =VLOOKUP(Table3[[#This Row],[Customer ID]],'Hospitalisation Details'!9:$1048576,10,FALSE()) -> tier - 2 | Q10: =VLOOKUP(Table3[[#This Row],[Customer ID]],'Hospitalisation Details'!9:$1048576,11,FALSE()) -> R1013
A11: Id10 | B11: =VLOOKUP(Table3[[#This Row],[Customer ID]],'Customer name 1'!10:$1048576,4,FALSE()) -> Ms. Brooke | C11: =VLOOKUP(Table3[[#This Row],[Customer ID]],'Medical Examinations'!$1:$1048576,2,FALSE()) -> 38.06 | D11: =VLOOKUP(Table3[[#This Row],[Customer ID]],'Medical Examinations'!$1:$1048576,3,FALSE()) -> obesity | E11: =VLOOKUP(Table3[[#This Row],[Customer ID]],'Medical Examinations'!$1:$1048576,4,FALSE()) -> 10.79 | F11: =VLOOKUP(Table3[[#This Row],[Customer ID]],'Medical Examinations'!$1:$1048576,5,FALSE()) -> diabetes | G11: =VLOOKUP(Table3[[#This Row],[Customer ID]],'Medical Examinations'!$1:$1048576,6,FALSE()) -> No | H11: =VLOOKUP(Table3[[#This Row],[Customer ID]],'Medical Examinations'!$1:$1048576,7,FALSE()) -> No | I11: =VLOOKUP(Table3[[#This Row],[Customer ID]],'Medical Examinations'!$1:$1048576,8,FALSE()) -> No | J11: =VLOOKUP(Table3[[#This Row],[Customer ID]],'Medical Examinations'!$1:$1048576,9,FALSE()) -> 0 | K11: =VLOOKUP(Table3[[#This Row],[Customer ID]],'Medical Examinations'!$1:$1048576,10,FALSE()) -> yes | L11: =VLOOKUP(Table3[[#This Row],[Customer ID]],'Hospitalisation Details'!10:$1048576,5,FALSE()) -> 29 Dec 1978 | M11: =VLOOKUP(Table3[[#This Row],[Customer ID]],'Hospitalisation Details'!10:$1048576,6,FALSE()) -> 44 | N11: =VLOOKUP(Table3[[#This Row],[Customer ID]],'Hospitalisation Details'!10:$1048576,8,FALSE()) -> 48885.14 | O11: =VLOOKUP(Table3[[#This Row],[Customer ID]],'Hospitalisation Details'!10:$1048576,9,FALSE()) -> tier - 1 | P11: =VLOOKUP(Table3[[#This Row],[Customer ID]],'Hospitalisation Details'!10:$1048576,10,FALSE()) -> tier - 2 | Q11: =VLOOKUP(Table3[[#This Row],[Customer ID]],'Hospitalisation Details'!10:$1048576,11,FALSE()) -> R1013
A12: Id11 | B12: =VLOOKUP(Table3[[#This Row],[Customer ID]],'Customer name 1'!11:$1048576,4,FALSE()) -> Ms. Paola | C12: =VLOOKUP(Table3[[#This Row],[Customer ID]],'Medical Examinations'!$1:$1048576,2,FALSE()) -> 37.7 | D12: =VLOOKUP(Table3[[#This Row],[Customer ID]],'Medical Examinations'!$1:$1048576,3,FALSE()) -> obesity | E12: =VLOOKUP(Table3[[#This Row],[Customer ID]],'Medical Examinations'!$1:$1048576,4,FALSE()) -> 5.96 | F12: =VLOOKUP(Table3[[#This Row],[Customer ID]],'Medical Examinations'!$1:$1048576,5,FALSE()) -> prediabetes | G12: =VLOOKUP(Table3[[#This Row],[Customer ID]],'Medical Examinations'!$1:$1048576,6,FALSE()) -> yes | H12: =VLOOKUP(Table3[[#This Row],[Customer ID]],'Medical Examinations'!$1:$1048576,7,FALSE()) -> No | I12: =VLOOKUP(Table3[[#This Row],[Customer ID]],'Medical Examinations'!$1:$1048576,8,FALSE()) -> No | J12: =VLOOKUP(Table3[[#This Row],[Customer ID]],'Medical Examinations'!$1:$1048576,9,FALSE()) -> 2 | K12: =VLOOKUP(Table3[[#This Row],[Customer ID]],'Medical Examinations'!$1:$1048576,10,FALSE()) -> yes | L12: =VLOOKUP(Table3[[#This Row],[Customer ID]],'Hospitalisation Details'!11:$1048576,5,FALSE()) -> 22 Jul 1959 | M12: =VLOOKUP(Table3[[#This Row],[Customer ID]],'Hospitalisation Details'!11:$1048576,6,FALSE()) -> 63 | N12: =VLOOKUP(Table3[[#This Row],[Customer ID]],'Hospitalisation Details'!11:$1048576,8,FALSE()) -> 48824.45 | O12: =VLOOKUP(Table3[[#This Row],[Customer ID]],'Hospitalisation Details'!11:$1048576,9,FALSE()) -> tier - 2 | P12: =VLOOKUP(Table3[[#This Row],[Customer ID]],'Hospitalisation Details'!11:$1048576,10,FALSE()) -> tier - 1 | Q12: =VLOOKUP(Table3[[#This Row],[Customer ID]],'Hospitalisation Details'!11:$1048576,11,FALSE()) -> R1011
A13: Id12 | B13: =VLOOKUP(Table3[[#This Row],[Customer ID]],'Customer name 1'!12:$1048576,4,FALSE()) -> Mr. David | C13: =VLOOKUP(Table3[[#This Row],[Customer ID]],'Medical Examinations'!$1:$1048576,2,FALSE()) -> 42.13 | D13: =VLOOKUP(Table3[[#This Row],[Customer ID]],'Medical Examinations'!$1:$1048576,3,FALSE()) -> obesity | E13: =VLOOKUP(Table3[[#This Row],[Customer ID]],'Medical Examinations'!$1:$1048576,4,FALSE()) -> 11.9 | F13: =VLOOKUP(Table3[[#This Row],[Customer ID]],'Medical Examinations'!$1:$1048576,5,FALSE()) -> diabetes | G13: =VLOOKUP(Table3[[#This Row],[Customer ID]],'Medical Examinations'!$1:$1048576,6,FALSE()) -> No | H13: =VLOOKUP(Table3[[#This Row],[Customer ID]],'Medical Examinations'!$1:$1048576,7,FALSE()) -> No | I13: =VLOOKUP(Table3[[#This Row],[Customer ID]],'Medical Examinations'!$1:$1048576,8,FALSE()) -> No | J13: =VLOOKUP(Table3[[#This Row],[Customer ID]],'Medical Examinations'!$1:$1048576,9,FALSE()) -> 0 | K13: =VLOOKUP(Table3[[#This Row],[Customer ID]],'Medical Examinations'!$1:$1048576,10,FALSE()) -> yes | L13: =VLOOKUP(Table3[[#This Row],[Customer ID]],'Hospitalisation Details'!12:$1048576,5,FALSE()) -> 27 Oct 1965 | M13: =VLOOKUP(Table3[[#This Row],[Customer ID]],'Hospitalisation Details'!12:$1048576,6,FALSE()) -> 57 | N13: =VLOOKUP(Table3[[#This Row],[Customer ID]],'Hospitalisation Details'!12:$1048576,8,FALSE()) -> 48675.52 | O13: =VLOOKUP(Table3[[#This Row],[Customer ID]],'Hospitalisation Details'!12:$1048576,9,FALSE()) -> tier - 1 | P13: =VLOOKUP(Table3[[#This Row],[Customer ID]],'Hospitalisation Details'!12:$1048576,10,FALSE()) -> tier - 2 | Q13: =VLOOKUP(Table3[[#This Row],[Customer ID]],'Hospitalisation Details'!12:$1048576,11,FALSE()) -> R1013
